Workbook

Sheet Dashboard
A1: Thai SET Trading Model — Live Signal Dashboard
A2: As of 10 April 2026 | Signals based on RSI(14), SMA50 cross, and MACD(12,26,9) | For educational purposes only — not financial advice
A3: Instrument | B3: Last Date | C3: Close Price | D3: RSI (14) | E3: SMA 20 | F3: SMA 50 | G3: SMA 200 | H3: RSI Signal | I3: MA Signal | J3: MACD Signal | K3: Score | L3: OVERALL SIGNAL
A4: SET_Index | B4: =SET_Index!A254 -> 46122 | C4: =SET_Index!E254 -> 1727.09 | D4: =SET_Index!M254 -> 44.217521 | E4: =SET_Index!N254 -> 1754.792 | F4: =SET_Index!O254 -> 1748.6124 | G4: =SET_Index!P254 -> 1564.1182 | H4: =SET_Index!V254 -> HOLD | I4: =SET_Index!W254 -> SELL | J4: =SET_Index!X254 -> SELL | K4: =SET_Index!Y254 -> -2 | L4: =SET_Index!Z254 -> STRONG SELL
A5: PTT | B5: =PTT!A254 -> 46122 | C5: =PTT!E254 -> 28.62 | D5: =PTT!M254 -> 44.388517 | E5: =PTT!N254 -> 28.967 | F5: =PTT!O254 -> 29.6456 | G5: =PTT!P254 -> 33.4211 | H5: =PTT!V254 -> HOLD | I5: =PTT!W254 -> SELL | J5: =PTT!X254 -> SELL | K5: =PTT!Y254 -> -2 | L5: =PTT!Z254 -> STRONG SELL
A6: KBANK | B6: =KBANK!A254 -> 46122 | C6: =KBANK!E254 -> 176.11 | D6: =KBANK!M254 -> 52.363123 | E6: =KBANK!N254 -> 177.406 | F6: =KBANK!O254 -> 167.6362 | G6: =KBANK!P254 -> 148.65285 | H6: =KBANK!V254 -> HOLD | I6: =KBANK!W254 -> BUY | J6: =KBANK!X254 -> SELL | K6: =KBANK!Y254 -> 0 | L6: =KBANK!Z254 -> HOLD
A7: AOT | B7: =AOT!A254 -> 46122 | C7: =AOT!E254 -> 65.27 | D7: =AOT!M254 -> 38.345555 | E7: =AOT!N254 -> 67.768 | F7: =AOT!O254 -> 69.233 | G7: =AOT!P254 -> 66.7676 | H7: =AOT!V254 -> HOLD | I7: =AOT!W254 -> SELL | J7: =AOT!X254 -> SELL | K7: =AOT!Y254 -> -2 | L7: =AOT!Z254 -> STRONG SELL
A8: ADVANC | B8: =ADVANC!A254 -> 46122 | C8: =ADVANC!E254 -> 248.13 | D8: =ADVANC!M254 -> 40.898125 | E8: =ADVANC!N254 -> 255.2925 | F8: =ADVANC!O254 -> 254.2184 | G8: =ADVANC!P254 -> 235.75285 | H8: =ADVANC!V254 -> HOLD | I8: =ADVANC!W254 -> SELL | J8: =ADVANC!X254 -> SELL | K8: =ADVANC!Y254 -> -2 | L8: =ADVANC!Z254 -> STRONG SELL
A11: HOW TO USE THIS MODEL
A12: 1. ENTER YOUR DATA: Go to any instrument sheet (SET_Index, PTT, KBANK, AOT, ADVANC). Replace the blue input cells (columns A–F) with real price data from your broker or Bloomberg.
A13: 2. ADJUST PARAMETERS: Go to the Assumptions sheet to change RSI thresholds, MA periods, etc. Signal formulas will auto-update.
A14: 3. READ SIGNALS: Each row shows RSI Signal, MA Signal, and MACD Signal. The OVERALL column combines all three: STRONG BUY (3/3 bullish), BUY (2/3), HOLD (mixed), SELL (2/3 bearish), STRONG SELL (3/3 bearish).
A15: 4. ADD MORE STOCKS: Duplicate any instrument sheet (right-click tab → Move or Copy) and replace the data in columns A–F with your new stock's data.
A16: 5. SIGNAL LOGIC: RSI Signal — RSI<30=BUY, RSI>70=SELL | MA Signal — Close>SMA50=BUY, Close<SMA50=SELL | MACD Signal — MACD>Signal=BUY, MACD<Signal=SELL
A17: ⚠ Note: SMA200 requires 200 days of data. Score/Overall signals begin after 50 days (when SMA50 becomes active). First 50 rows show partial signals only.

Sheet SET_Index
A1: Thai SET Trading Model | SET_Index | Rule-Based Buy/Sell Signals
A2: Date | B2: Open | C2: High | D2: Low | E2: Close (Points) | F2: Volume | G2: Change | H2: % Change | I2: Gain | J2: Loss | K2: Avg Gain 14 | L2: Avg Loss 14 | M2: RSI (14) | N2: SMA 20 | O2: SMA 50 | P2: SMA 200 | Q2: EMA 12 | R2: EMA 26 | S2: MACD Line | T2: Signal Line | U2: Histogram | V2: RSI Signal | W2: MA Signal | X2: MACD Signal | Y2: Score | Z2: OVERALL
A3: 45771 | B3: 1360.4 | C3: 1367.42 | D3: 1342.58 | E3: 1355 | F3: 5852946
A4: 45772 | B4: 1353.2 | C4: 1380.42 | D4: 1326.34 | E4: 1353.38 | F4: 6085611 | G4: =E4-E3 -> -1.62 | H4: =G4/E3 -> -0.001195572 | I4: =MAX(G4,0) -> 0 | J4: =MAX(-G4,0) -> 1.62
A5: 45775 | B5: 1350.21 | C5: 1353.9 | D5: 1348.92 | E5: 1351.41 | F5: 9053299 | G5: =E5-E4 -> -1.97 | H5: =G5/E4 -> -0.0014556148 | I5: =MAX(G5,0) -> 0 | J5: =MAX(-G5,0) -> 1.97
A6: 45776 | B6: 1342.65 | C6: 1362.4 | D6: 1337.98 | E6: 1350.19 | F6: 4300268 | G6: =E6-E5 -> -1.22 | H6: =G6/E5 -> -0.00090276082 | I6: =MAX(G6,0) -> 0 | J6: =MAX(-G6,0) -> 1.22
A7: 45777 | B7: 1362.37 | C7: 1362.37 | D7: 1355.39 | E7: 1358.88 | F7: 2640217 | G7: =E7-E6 -> 8.69 | H7: =G7/E6 -> 0.0064361312 | I7: =MAX(G7,0) -> 8.69 | J7: =MAX(-G7,0) -> 0
A8: 45778 | B8: 1347.15 | C8: 1375.83 | D8: 1339.09 | E8: 1357.46 | F8: 4875554 | G8: =E8-E7 -> -1.42 | H8: =G8/E7 -> -0.0010449782 | I8: =MAX(G8,0) -> 0 | J8: =MAX(-G8,0) -> 1.42
A9: 45779 | B9: 1340.25 | C9: 1340.25 | D9: 1338.59 | E9: 1339.42 | F9: 3653069 | G9: =E9-E8 -> -18.04 | H9: =G9/E8 -> -0.013289526 | I9: =MAX(G9,0) -> 0 | J9: =MAX(-G9,0) -> 18.04
A10: 45782 | B10: 1333.7 | C10: 1353.44 | D10: 1333.7 | E10: 1343.57 | F10: 5576077 | G10: =E10-E9 -> 4.15 | H10: =G10/E9 -> 0.003098356 | I10: =MAX(G10,0) -> 4.15 | J10: =MAX(-G10,0) -> 0
A11: 45783 | B11: 1343.46 | C11: 1343.46 | D11: 1337.5 | E11: 1340.48 | F11: 6383892 | G11: =E11-E10 -> -3.09 | H11: =G11/E10 -> -0.002299843 | I11: =MAX(G11,0) -> 0 | J11: =MAX(-G11,0) -> 3.09
A12: 45784 | B12: 1339.53 | C12: 1339.53 | D12: 1336.47 | E12: 1338 | F12: 4761357 | G12: =E12-E11 -> -2.48 | H12: =G12/E11 -> -0.0018500836 | I12: =MAX(G12,0) -> 0 | J12: =MAX(-G12,0) -> 2.48
A13: 45785 | B13: 1336.74 | C13: 1344.84 | D13: 1334.22 | E13: 1339.53 | F13: 3976579 | G13: =E13-E12 -> 1.53 | H13: =G13/E12 -> 0.0011434978 | I13: =MAX(G13,0) -> 1.53 | J13: =MAX(-G13,0) -> 0
A14: 45786 | B14: 1343.31 | C14: 1359.91 | D14: 1325.03 | E14: 1342.47 | F14: 5437299 | G14: =E14-E13 -> 2.94 | H14: =G14/E13 -> 0.0021947997 | I14: =MAX(G14,0) -> 2.94 | J14: =MAX(-G14,0) -> 0 | Q14: =AVERAGE(E3:E14) -> 1347.4825
A15: 45789 | B15: 1353.79 | C15: 1359.69 | D15: 1353.79 | E15: 1356.74 | F15: 5650656 | G15: =E15-E14 -> 14.27 | H15: =G15/E14 -> 0.01062966 | I15: =MAX(G15,0) -> 14.27 | J15: =MAX(-G15,0) -> 0 | Q15: =Q14+(2/13)*(E15-Q14) -> 1348.9067
A16: 45790 | B16: 1365.13 | C16: 1378.98 | D16: 1350.86 | E16: 1364.92 | F16: 4111641 | G16: =E16-E15 -> 8.18 | H16: =G16/E15 -> 0.0060291581 | I16: =MAX(G16,0) -> 8.18 | J16: =MAX(-G16,0) -> 0 | Q16: =Q15+(2/13)*(E16-Q15) -> 1351.3703
A17: 45791 | B17: 1366.03 | C17: 1371.26 | D17: 1361.56 | E17: 1366.41 | F17: 2786660 | G17: =E17-E16 -> 1.49 | H17: =G17/E16 -> 0.0010916391 | I17: =MAX(G17,0) -> 1.49 | J17: =MAX(-G17,0) -> 0 | K17: =AVERAGE(I4:I17) -> 2.9464286 | L17: =AVERAGE(J4:J17) -> 2.1314286 | M17: =IF(L17=0,100,100-100/(1+K17/MAX(L17,0.000001))) -> 58.025039 | Q17: =Q16+(2/13)*(E17-Q16) -> 1353.6841 | V17: =IF(M17="","",IF(M17<Assumptions!$B$5,"BUY",IF(M17>Assumptions!$B$4,"SELL","HOLD"))) -> HOLD
A18: 45792 | B18: 1357.83 | C18: 1358.52 | D18: 1356.48 | E18: 1357.5 | F18: 8228187 | G18: =E18-E17 -> -8.91 | H18: =G18/E17 -> -0.0065207368 | I18: =MAX(G18,0) -> 0 | J18: =MAX(-G18,0) -> 8.91 | K18: =(K17*13+I18)/14 -> 2.7359694 | L18: =(L17*13+J18)/14 -> 2.6156122 | M18: =IF(L18=0,100,100-100/(1+K18/MAX(L18,0.000001))) -> 51.124501 | Q18: =Q17+(2/13)*(E18-Q17) -> 1354.2712 | V18: =IF(M18="","",IF(M18<Assumptions!$B$5,"BUY",IF(M18>Assumptions!$B$4,"SELL","HOLD"))) -> HOLD
A19: 45793 | B19: 1350.87 | C19: 1352.91 | D19: 1337.67 | E19: 1345.29 | F19: 3752340 | G19: =E19-E18 -> -12.21 | H19: =G19/E18 -> -0.0089944751 | I19: =MAX(G19,0) -> 0 | J19: =MAX(-G19,0) -> 12.21 | K19: =(K18*13+I19)/14 -> 2.540543 | L19: =(L18*13+J19)/14 -> 3.3009257 | M19: =IF(L19=0,100,100-100/(1+K19/MAX(L19,0.000001))) -> 43.491511 | Q19: =Q18+(2/13)*(E19-Q18) -> 1352.8895 | V19: =IF(M19="","",IF(M19<Assumptions!$B$5,"BUY",IF(M19>Assumptions!$B$4,"SELL","HOLD"))) -> HOLD
A20: 45796 | B20: 1342.99 | C20: 1353.83 | D20: 1342.99 | E20: 1348.41 | F20: 5545931 | G20: =E20-E19 -> 3.12 | H20: =G20/E19 -> 0.0023192026 | I20: =MAX(G20,0) -> 3.12 | J20: =MAX(-G20,0) -> 0 | K20: =(K19*13+I20)/14 -> 2.5819328 | L20: =(L19*13+J20)/14 -> 3.0651453 | M20: =IF(L20=0,100,100-100/(1+K20/MAX(L20,0.000001))) -> 45.721571 | Q20: =Q19+(2/13)*(E20-Q19) -> 1352.2003 | V20: =IF(M20="","",IF(M20<Assumptions!$B$5,"BUY",IF(M20>Assumptions!$B$4,"SELL","HOLD"))) -> HOLD
A21: 45797 | B21: 1361.12 | C21: 1367.98 | D21: 1361.12 | E21: 1364.55 | F21: 8498914 | G21: =E21-E20 -> 16.14 | H21: =G21/E20 -> 0.011969653 | I21: =MAX(G21,0) -> 16.14 | J21: =MAX(-G21,0) -> 0 | K21: =(K20*13+I21)/14 -> 3.5503662 | L21: =(L20*13+J21)/14 -> 2.8462063 | M21: =IF(L21=0,100,100-100/(1+K21/MAX(L21,0.000001))) -> 55.504197 | Q21: =Q20+(2/13)*(E21-Q20) -> 1354.1003 | V21: =IF(M21="","",IF(M21<Assumptions!$B$5,"BUY",IF(M21>Assumptions!$B$4,"SELL","HOLD"))) -> HOLD
A22: 45798 | B22: 1360.55 | C22: 1369.85 | D22: 1360.55 | E22: 1365.2 | F22: 5967504 | G22: =E22-E21 -> 0.65 | H22: =G22/E21 -> 0.00047634751 | I22: =MAX(G22,0) -> 0.65 | J22: =MAX(-G22,0) -> 0 | K22: =(K21*13+I22)/14 -> 3.3431971 | L22: =(L21*13+J22)/14 -> 2.6429059 | M22: =IF(L22=0,100,100-100/(1+K22/MAX(L22,0.000001))) -> 55.849309 | N22: =AVERAGE(E3:E22) -> 1351.9405 | Q22: =Q21+(2/13)*(E22-Q21) -> 1355.8079 | V22: =IF(M22="","",IF(M22<Assumptions!$B$5,"BUY",IF(M22>Assumptions!$B$4,"SELL","HOLD"))) -> HOLD
A23: 45799 | B23: 1364.04 | C23: 1367.36 | D23: 1360.7 | E23: 1364.03 | F23: 5815088 | G23: =E23-E22 -> -1.17 | H23: =G23/E22 -> -0.00085701729 | I23: =MAX(G23,0) -> 0 | J23: =MAX(-G23,0) -> 1.17 | K23: =(K22*13+I23)/14 -> 3.1043974 | L23: =(L22*13+J23)/14 -> 2.5376983 | M23: =IF(L23=0,100,100-100/(1+K23/MAX(L23,0.000001))) -> 55.022062 | N23: =AVERAGE(E4:E23) -> 1352.392 | Q23: =Q22+(2/13)*(E23-Q22) -> 1357.0728 | V23: =IF(M23="","",IF(M23<Assumptions!$B$5,"BUY",IF(M23>Assumptions!$B$4,"SELL","HOLD"))) -> HOLD
A24: 45800 | B24: 1367.5 | C24: 1373.92 | D24: 1367.5 | E24: 1370.71 | F24: 2972940 | G24: =E24-E23 -> 6.68 | H24: =G24/E23 -> 0.004897253 | I24: =MAX(G24,0) -> 6.68 | J24: =MAX(-G24,0) -> 0 | K24: =(K23*13+I24)/14 -> 3.3597975 | L24: =(L23*13+J24)/14 -> 2.3564341 | M24: =IF(L24=0,100,100-100/(1+K24/MAX(L24,0.000001))) -> 58.776441 | N24: =AVERAGE(E5:E24) -> 1353.2585 | Q24: =Q23+(2/13)*(E24-Q23) -> 1359.1709 | V24: =IF(M24="","",IF(M24<Assumptions!$B$5,"BUY",IF(M24>Assumptions!$B$4,"SELL","HOLD"))) -> HOLD
A25: 45803 | B25: 1359.3 | C25: 1359.3 | D25: 1346.76 | E25: 1353.03 | F25: 8330517 | G25: =E25-E24 -> -17.68 | H25: =G25/E24 -> -0.012898425 | I25: =MAX(G25,0) -> 0 | J25: =MAX(-G25,0) -> 17.68 | K25: =(K24*13+I25)/14 -> 3.119812 | L25: =(L24*13+J25)/14 -> 3.4509745 | M25: =IF(L25=0,100,100-100/(1+K25/MAX(L25,0.000001))) -> 47.480039 | N25: =AVERAGE(E6:E25) -> 1353.3395 | Q25: =Q24+(2/13)*(E25-Q24) -> 1358.2261 | V25: =IF(M25="","",IF(M25<Assumptions!$B$5,"BUY",IF(M25>Assumptions!$B$4,"SELL","HOLD"))) -> HOLD
A26: 45804 | B26: 1338.32 | C26: 1363.97 | D26: 1334.77 | E26: 1349.37 | F26: 6346593 | G26: =E26-E25 -> -3.66 | H26: =G26/E25 -> -0.0027050398 | I26: =MAX(G26,0) -> 0 | J26: =MAX(-G26,0) -> 3.66 | K26: =(K25*13+I26)/14 -> 2.8969683 | L26: =(L25*13+J26)/14 -> 3.4659049 | M26: =IF(L26=0,100,100-100/(1+K26/MAX(L26,0.000001))) -> 45.529247 | N26: =AVERAGE(E7:E26) -> 1353.2985 | Q26: =Q25+(2/13)*(E26-Q25) -> 1356.8636 | V26: =IF(M26="","",IF(M26<Assumptions!$B$5,"BUY",IF(M26>Assumptions!$B$4,"SELL","HOLD"))) -> HOLD
A27: 45805 | B27: 1364.25 | C27: 1371.05 | D27: 1339.89 | E27: 1355.47 | F27: 5443361 | G27: =E27-E26 -> 6.1 | H27: =G27/E26 -> 0.0045206281 | I27: =MAX(G27,0) -> 6.1 | J27: =MAX(-G27,0) -> 0 | K27: =(K26*13+I27)/14 -> 3.1257563 | L27: =(L26*13+J27)/14 -> 3.2183403 | M27: =IF(L27=0,100,100-100/(1+K27/MAX(L27,0.000001))) -> 49.270314 | N27: =AVERAGE(E8:E27) -> 1353.128 | Q27: =Q26+(2/13)*(E27-Q26) -> 1356.6492 | V27: =IF(M27="","",IF(M27<Assumptions!$B$5,"BUY",IF(M27>Assumptions!$B$4,"SELL","HOLD"))) -> HOLD
A28: 45806 | B28: 1375.66 | C28: 1375.66 | D28: 1356.94 | E28: 1366.3 | F28: 6126949 | G28: =E28-E27 -> 10.83 | H28: =G28/E27 -> 0.0079898485 | I28: =MAX(G28,0) -> 10.83 | J28: =MAX(-G28,0) -> 0 | K28: =(K27*13+I28)/14 -> 3.6760594 | L28: =(L27*13+J28)/14 -> 2.9884589 | M28: =IF(L28=0,100,100-100/(1+K28/MAX(L28,0.000001))) -> 55.158667 | N28: =AVERAGE(E9:E28) -> 1353.57 | Q28: =Q27+(2/13)*(E28-Q27) -> 1358.134 | R28: =AVERAGE(E3:E28) -> 1353.7585 | S28: =Q28-R28 -> 4.3755064 | V28: =IF(M28="","",IF(M28<Assumptions!$B$5,"BUY",IF(M28>Assumptions!$B$4,"SELL","HOLD"))) -> HOLD
A29: 45807 | B29: 1365.08 | C29: 1378.95 | D29: 1348.01 | E29: 1363.48 | F29: 3720505 | G29: =E29-E28 -> -2.82 | H29: =G29/E28 -> -0.0020639684 | I29: =MAX(G29,0) -> 0 | J29: =MAX(-G29,0) -> 2.82 | K29: =(K28*13+I29)/14 -> 3.4134837 | L29: =(L28*13+J29)/14 -> 2.9764261 | M29: =IF(L29=0,100,100-100/(1+K29/MAX(L29,0.000001))) -> 53.419905 | N29: =AVERAGE(E10:E29) -> 1354.773 | Q29: =Q28+(2/13)*(E29-Q28) -> 1358.9564 | R29: =R28+(2/27)*(E29-R28) -> 1354.4786 | S29: =Q29-R29 -> 4.4778589 | V29: =IF(M29="","",IF(M29<Assumptions!$B$5,"BUY",IF(M29>Assumptions!$B$4,"SELL","HOLD"))) -> HOLD
A30: 45810 | B30: 1367.34 | C30: 1369.16 | D30: 1367.34 | E30: 1368.25 | F30: 7403614 | G30: =E30-E29 -> 4.77 | H30: =G30/E29 -> 0.0034984011 | I30: =MAX(G30,0) -> 4.77 | J30: =MAX(-G30,0) -> 0 | K30: =(K29*13+I30)/14 -> 3.5103777 | L30: =(L29*13+J30)/14 -> 2.7638242 | M30: =IF(L30=0,100,100-100/(1+K30/MAX(L30,0.000001))) -> 55.94939 | N30: =AVERAGE(E11:E30) -> 1356.007 | Q30: =Q29+(2/13)*(E30-Q29) -> 1360.3862 | R30: =R29+(2/27)*(E30-R29) -> 1355.4987 | S30: =Q30-R30 -> 4.8875327 | V30: =IF(M30="","",IF(M30<Assumptions!$B$5,"BUY",IF(M30>Assumptions!$B$4,"SELL","HOLD"))) -> HOLD
A31: 45811 | B31: 1373.19 | C31: 1383.16 | D31: 1359.74 | E31: 1371.45 | F31: 8174829 | G31: =E31-E30 -> 3.2 | H31: =G31/E30 -> 0.0023387539 | I31: =MAX(G31,0) -> 3.2 | J31: =MAX(-G31,0) -> 0 | K31: =(K30*13+I31)/14 -> 3.4882079 | L31: =(L30*13+J31)/14 -> 2.5664082 | M31: =IF(L31=0,100,100-100/(1+K31/MAX(L31,0.000001))) -> 57.612371 | N31: =AVERAGE(E12:E31) -> 1357.5555 | Q31: =Q30+(2/13)*(E31-Q30) -> 1362.0883 | R31: =R30+(2/27)*(E31-R30) -> 1356.6803 | S31: =Q31-R31 -> 5.4080745 | V31: =IF(M31="","",IF(M31<Assumptions!$B$5,"BUY",IF(M31>Assumptions!$B$4,"SELL","HOLD"))) -> HOLD
A32: 45812 | B32: 1382.44 | C32: 1388.13 | D32: 1374.43 | E32: 1381.28 | F32: 5353502 | G32: =E32-E31 -> 9.83 | H32: =G32/E31 -> 0.0071675963 | I32: =MAX(G32,0) -> 9.83 | J32: =MAX(-G32,0) -> 0 | K32: =(K31*13+I32)/14 -> 3.9411931 | L32: =(L31*13+J32)/14 -> 2.3830933 | M32: =IF(L32=0,100,100-100/(1+K32/MAX(L32,0.000001))) -> 62.318384 | N32: =AVERAGE(E13:E32) -> 1359.7195 | Q32: =Q31+(2/13)*(E32-Q31) -> 1365.0409 | R32: =R31+(2/27)*(E32-R31) -> 1358.5025 | S32: =Q32-R32 -> 6.5384354 | V32: =IF(M32="","",IF(M32<Assumptions!$B$5,"BUY",IF(M32>Assumptions!$B$4,"SELL","HOLD"))) -> HOLD
A33: 45813 | B33: 1371.2 | C33: 1373.31 | D33: 1361.99 | E33: 1367.65 | F33: 5169837 | G33: =E33-E32 -> -13.63 | H33: =G33/E32 -> -0.009867659 | I33: =MAX(G33,0) -> 0 | J33: =MAX(-G33,0) -> 13.63 | K33: =(K32*13+I33)/14 -> 3.6596793 | L33: =(L32*13+J33)/14 -> 3.1864438 | M33: =IF(L33=0,100,100-100/(1+K33/MAX(L33,0.000001))) -> 53.45623 | N33: =AVERAGE(E14:E33) -> 1361.1255 | Q33: =Q32+(2/13)*(E33-Q32) -> 1365.4423 | R33: =R32+(2/27)*(E33-R32) -> 1359.1801 | S33: =Q33-R33 -> 6.2622403 | V33: =IF(M33="","",IF(M33<Assumptions!$B$5,"BUY",IF(M33>Assumptions!$B$4,"SELL","HOLD"))) -> HOLD
A34: 45814 | B34: 1382.58 | C34: 1382.58 | D34: 1367.02 | E34: 1374.8 | F34: 6385326 | G34: =E34-E33 -> 7.15 | H34: =G34/E33 -> 0.0052279457 | I34: =MAX(G34,0) -> 7.15 | J34: =MAX(-G34,0) -> 0 | K34: =(K33*13+I34)/14 -> 3.9089879 | L34: =(L33*13+J34)/14 -> 2.9588407 | M34: =IF(L34=0,100,100-100/(1+K34/MAX(L34,0.000001))) -> 56.917377 | N34: =AVERAGE(E15:E34) -> 1362.742 | Q34: =Q33+(2/13)*(E34-Q33) -> 1366.8819 | R34: =R33+(2/27)*(E34-R33) -> 1360.3371 | S34: =Q34-R34 -> 6.544854 | V34: =IF(M34="","",IF(M34<Assumptions!$B$5,"BUY",IF(M34>Assumptions!$B$4,"SELL","HOLD"))) -> HOLD
A35: 45817 | B35: 1354.96 | C35: 1357.68 | D35: 1354.96 | E35: 1356.32 | F35: 3627365 | G35: =E35-E34 -> -18.48 | H35: =G35/E34 -> -0.013441955 | I35: =MAX(G35,0) -> 0 | J35: =MAX(-G35,0) -> 18.48 | K35: =(K34*13+I35)/14 -> 3.6297745 | L35: =(L34*13+J35)/14 -> 4.0674949 | M35: =IF(L35=0,100,100-100/(1+K35/MAX(L35,0.000001))) -> 47.156651 | N35: =AVERAGE(E16:E35) -> 1362.721 | Q35: =Q34+(2/13)*(E35-Q34) -> 1365.257 | R35: =R34+(2/27)*(E35-R34) -> 1360.0395 | S35: =Q35-R35 -> 5.2175016 | V35: =IF(M35="","",IF(M35<Assumptions!$B$5,"BUY",IF(M35>Assumptions!$B$4,"SELL","HOLD"))) -> HOLD
A36: 45818 | B36: 1324.07 | C36: 1334.63 | D36: 1315.07 | E36: 1324.85 | F36: 5804016 | G36: =E36-E35 -> -31.47 | H36: =G36/E35 -> -0.023202489 | I36: =MAX(G36,0) -> 0 | J36: =MAX(-G36,0) -> 31.47 | K36: =(K35*13+I36)/14 -> 3.3705049 | L36: =(L35*13+J36)/14 -> 6.0248167 | M36: =IF(L36=0,100,100-100/(1+K36/MAX(L36,0.000001))) -> 35.87429 | N36: =AVERAGE(E17:E36) -> 1360.7175 | Q36: =Q35+(2/13)*(E36-Q35) -> 1359.0406 | R36: =R35+(2/27)*(E36-R35) -> 1357.4329 | S36: =Q36-R36 -> 1.6076672 | T36: =AVERAGE(S28:S36) -> 5.035519 | U36: =S36-T36 -> -3.4278518 | V36: =IF(M36="","",IF(M36<Assumptions!$B$5,"BUY",IF(M36>Assumptions!$B$4,"SELL","HOLD"))) -> HOLD | X36: =IF(T36="","",IF(S36>T36,"BUY","SELL")) -> SELL
A37: 45819 | B37: 1319.23 | C37: 1319.23 | D37: 1316.31 | E37: 1317.77 | F37: 4797036 | G37: =E37-E36 -> -7.08 | H37: =G37/E36 -> -0.0053440012 | I37: =MAX(G37,0) -> 0 | J37: =MAX(-G37,0) -> 7.08 | K37: =(K36*13+I37)/14 -> 3.1297545 | L37: =(L36*13+J37)/14 -> 6.1001869 | M37: =IF(L37=0,100,100-100/(1+K37/MAX(L37,0.000001))) -> 33.908715 | N37: =AVERAGE(E18:E37) -> 1358.2855 | Q37: =Q36+(2/13)*(E37-Q36) -> 1352.6912 | R37: =R36+(2/27)*(E37-R36) -> 1354.4949 | S37: =Q37-R37 -> -1.803658 | T37: =T36+(2/10)*(S37-T36) -> 3.6676836 | U37: =S37-T37 -> -5.4713416 | V37: =IF(M37="","",IF(M37<Assumptions!$B$5,"BUY",IF(M37>Assumptions!$B$4,"SELL","HOLD"))) -> HOLD | X37: =IF(T37="","",IF(S37>T37,"BUY","SELL")) -> SELL
A38: 45820 | B38: 1306.12 | C38: 1313.07 | D38: 1301.09 | E38: 1307.08 | F38: 6451777 | G38: =E38-E37 -> -10.69 | H38: =G38/E37 -> -0.0081121895 | I38: =MAX(G38,0) -> 0 | J38: =MAX(-G38,0) -> 10.69 | K38: =(K37*13+I38)/14 -> 2.9062006 | L38: =(L37*13+J38)/14 -> 6.4280307 | M38: =IF(L38=0,100,100-100/(1+K38/MAX(L38,0.000001))) -> 31.134868 | N38: =AVERAGE(E19:E38) -> 1355.7645 | Q38: =Q37+(2/13)*(E38-Q37) -> 1345.6741 | R38: =R37+(2/27)*(E38-R37) -> 1350.9827 | S38: =Q38-R38 -> -5.3085577 | T38: =T37+(2/10)*(S38-T37) -> 1.8724353 | U38: =S38-T38 -> -7.1809931 | V38: =IF(M38="","",IF(M38<Assumptions!$B$5,"BUY",IF(M38>Assumptions!$B$4,"SELL","HOLD"))) -> HOLD | X38: =IF(T38="","",IF(S38>T38,"BUY","SELL")) -> SELL
A39: 45821 | B39: 1316.95 | C39: 1322.88 | D39: 1312.24 | E39: 1317.56 | F39: 3495389 | G39: =E39-E38 -> 10.48 | H39: =G39/E38 -> 0.0080178719 | I39: =MAX(G39,0) -> 10.48 | J39: =MAX(-G39,0) -> 0 | K39: =(K38*13+I39)/14 -> 3.4471863 | L39: =(L38*13+J39)/14 -> 5.9688857 | M39: =IF(L39=0,100,100-100/(1+K39/MAX(L39,0.000001))) -> 36.6096 | N39: =AVERAGE(E20:E39) -> 1354.378 | Q39: =Q38+(2/13)*(E39-Q38) -> 1341.3489 | R39: =R38+(2/27)*(E39-R38) -> 1348.5069 | S39: =Q39-R39 -> -7.158054 | T39: =T38+(2/10)*(S39-T38) -> 0.066337465 | U39: =S39-T39 -> -7.2243915 | V39: =IF(M39="","",IF(M39<Assumptions!$B$5,"BUY",IF(M39>Assumptions!$B$4,"SELL","HOLD"))) -> HOLD | X39: =IF(T39="","",IF(S39>T39,"BUY","SELL")) -> SELL
A40: 45824 | B40: 1321.67 | C40: 1333.07 | D40: 1318.11 | E40: 1325.59 | F40: 3277146 | G40: =E40-E39 -> 8.03 | H40: =G40/E39 -> 0.0060945991 | I40: =MAX(G40,0) -> 8.03 | J40: =MAX(-G40,0) -> 0 | K40: =(K39*13+I40)/14 -> 3.7745301 | L40: =(L39*13+J40)/14 -> 5.5425367 | M40: =IF(L40=0,100,100-100/(1+K40/MAX(L40,0.000001))) -> 40.512 | N40: =AVERAGE(E21:E40) -> 1353.237 | Q40: =Q39+(2/13)*(E40-Q39) -> 1338.9244 | R40: =R39+(2/27)*(E40-R39) -> 1346.8094 | S40: =Q40-R40 -> -7.8849465 | T40: =T39+(2/10)*(S40-T39) -> -1.5239193 | U40: =S40-T40 -> -6.3610272 | V40: =IF(M40="","",IF(M40<Assumptions!$B$5,"BUY",IF(M40>Assumptions!$B$4,"SELL","HOLD"))) -> HOLD | X40: =IF(T40="","",IF(S40>T40,"BUY","SELL")) -> SELL
...

Sheet Assumptions
A1: Thai SET Trading Model — Assumptions & Legend
A2: Parameter | B2: Value | C2: Description / Notes
A3: RSI Period (days) | B3: 14 | C3: Lookback window for RSI — standard is 14
A4: RSI Overbought Threshold | B4: 70 | C4: RSI above this → SELL signal (overbought)
A5: RSI Oversold Threshold | B5: 30 | C5: RSI below this → BUY signal (oversold)
A6: SMA Short Period | B6: 20 | C6: Fast simple moving average
A7: SMA Medium Period | B7: 50 | C7: Medium-term SMA (trend confirmation)
A8: SMA Long Period | B8: 200 | C8: Long-term SMA (major trend baseline)
A9: EMA Fast (MACD) | B9: 12 | C9: Fast EMA for MACD line calculation
A10: EMA Slow (MACD) | B10: 26 | C10: Slow EMA for MACD line calculation
A11: MACD Signal Period | B11: 9 | C11: Signal line smoothing (EMA of MACD)
A13: Color Coding Legend
A14: Blue text | B14: Sample | C14: Hardcoded inputs — change these to adjust scenarios
A15: Black text | B15: Sample | C15: Formulas & calculations — do not edit
A16: Green text | B16: Sample | C16: Cross-sheet links pulling from other worksheets
A17: Yellow fill | B17: Sample | C17: Key assumptions requiring attention
A18: Green fill | B18: Sample | C18: STRONG BUY signal
A19: Light green | B19: Sample | C19: BUY signal
A20: Gray fill | B20: Sample | C20: HOLD / neutral signal
A21: Light red | B21: Sample | C21: SELL signal
A22: Red fill | B22: Sample | C22: STRONG SELL signal
A24: ⚠ DISCLAIMER: This model is for informational and educational purposes only. It does not constitute financial advice. Past signals do not guarantee future returns. Always conduct your own research before making investment decisions.

Sheet PTT
A1: Thai SET Trading Model | PTT | Rule-Based Buy/Sell Signals
A2: Date | B2: Open | C2: High | D2: Low | E2: Close (THB) | F2: Volume | G2: Change | H2: % Change | I2: Gain | J2: Loss | K2: Avg Gain 14 | L2: Avg Loss 14 | M2: RSI (14) | N2: SMA 20 | O2: SMA 50 | P2: SMA 200 | Q2: EMA 12 | R2: EMA 26 | S2: MACD Line | T2: Signal Line | U2: Histogram | V2: RSI Signal | W2: MA Signal | X2: MACD Signal | Y2: Score | Z2: OVERALL
A3: 45771 | B3: 37.61 | C3: 37.61 | D3: 37.39 | E3: 37.5 | F3: 53648967
A4: 45772 | B4: 37.82 | C4: 37.82 | D4: 37.68 | E4: 37.75 | F4: 72694061 | G4: =E4-E3 -> 0.25 | H4: =G4/E3 -> 0.0066666667 | I4: =MAX(G4,0) -> 0.25 | J4: =MAX(-G4,0) -> 0
A5: 45775 | B5: 38.29 | C5: 38.29 | D5: 37.89 | E5: 38.09 | F5: 39233227 | G5: =E5-E4 -> 0.34 | H5: =G5/E4 -> 0.0090066225 | I5: =MAX(G5,0) -> 0.34 | J5: =MAX(-G5,0) -> 0
A6: 45776 | B6: 37.62 | C6: 37.62 | D6: 37.62 | E6: 37.62 | F6: 68778204 | G6: =E6-E5 -> -0.47 | H6: =G6/E5 -> -0.012339197 | I6: =MAX(G6,0) -> 0 | J6: =MAX(-G6,0) -> 0.47
A7: 45777 | B7: 37.3 | C7: 37.48 | D7: 36.98 | E7: 37.23 | F7: 59170260 | G7: =E7-E6 -> -0.39 | H7: =G7/E6 -> -0.010366826 | I7: =MAX(G7,0) -> 0 | J7: =MAX(-G7,0) -> 0.39
A8: 45778 | B8: 36.57 | C8: 36.78 | D8: 36.42 | E8: 36.6 | F8: 67559714 | G8: =E8-E7 -> -0.63 | H8: =G8/E7 -> -0.016921837 | I8: =MAX(G8,0) -> 0 | J8: =MAX(-G8,0) -> 0.63
A9: 45779 | B9: 36.68 | C9: 36.68 | D9: 36.36 | E9: 36.52 | F9: 56164202 | G9: =E9-E8 -> -0.08 | H9: =G9/E8 -> -0.0021857923 | I9: =MAX(G9,0) -> 0 | J9: =MAX(-G9,0) -> 0.08
A10: 45782 | B10: 36.52 | C10: 36.77 | D10: 36.15 | E10: 36.46 | F10: 53137830 | G10: =E10-E9 -> -0.06 | H10: =G10/E9 -> -0.0016429354 | I10: =MAX(G10,0) -> 0 | J10: =MAX(-G10,0) -> 0.06
A11: 45783 | B11: 36.47 | C11: 36.63 | D11: 36.47 | E11: 36.55 | F11: 45796623 | G11: =E11-E10 -> 0.09 | H11: =G11/E10 -> 0.0024684586 | I11: =MAX(G11,0) -> 0.09 | J11: =MAX(-G11,0) -> 0
A12: 45784 | B12: 36.43 | C12: 36.49 | D12: 35.87 | E12: 36.18 | F12: 30255120 | G12: =E12-E11 -> -0.37 | H12: =G12/E11 -> -0.010123119 | I12: =MAX(G12,0) -> 0 | J12: =MAX(-G12,0) -> 0.37
A13: 45785 | B13: 36.8 | C13: 36.8 | D13: 36.5 | E13: 36.65 | F13: 60238039 | G13: =E13-E12 -> 0.47 | H13: =G13/E12 -> 0.012990603 | I13: =MAX(G13,0) -> 0.47 | J13: =MAX(-G13,0) -> 0
A14: 45786 | B14: 37.29 | C14: 37.29 | D14: 36.97 | E14: 37.13 | F14: 44537502 | G14: =E14-E13 -> 0.48 | H14: =G14/E13 -> 0.013096862 | I14: =MAX(G14,0) -> 0.48 | J14: =MAX(-G14,0) -> 0 | Q14: =AVERAGE(E3:E14) -> 37.023333
A15: 45789 | B15: 38.08 | C15: 38.19 | D15: 37.71 | E15: 37.95 | F15: 63934870 | G15: =E15-E14 -> 0.82 | H15: =G15/E14 -> 0.022084568 | I15: =MAX(G15,0) -> 0.82 | J15: =MAX(-G15,0) -> 0 | Q15: =Q14+(2/13)*(E15-Q14) -> 37.165897
A16: 45790 | B16: 38.25 | C16: 38.41 | D16: 38.25 | E16: 38.33 | F16: 71685134 | G16: =E16-E15 -> 0.38 | H16: =G16/E15 -> 0.010013175 | I16: =MAX(G16,0) -> 0.38 | J16: =MAX(-G16,0) -> 0 | Q16: =Q15+(2/13)*(E16-Q15) -> 37.34499
A17: 45791 | B17: 38.3 | C17: 38.56 | D17: 38.3 | E17: 38.43 | F17: 63649191 | G17: =E17-E16 -> 0.1 | H17: =G17/E16 -> 0.0026089225 | I17: =MAX(G17,0) -> 0.1 | J17: =MAX(-G17,0) -> 0 | K17: =AVERAGE(I4:I17) -> 0.20928571 | L17: =AVERAGE(J4:J17) -> 0.14285714 | M17: =IF(L17=0,100,100-100/(1+K17/MAX(L17,0.000001))) -> 59.432049 | Q17: =Q16+(2/13)*(E17-Q16) -> 37.511915 | V17: =IF(M17="","",IF(M17<Assumptions!$B$5,"BUY",IF(M17>Assumptions!$B$4,"SELL","HOLD"))) -> HOLD
A18: 45792 | B18: 38.73 | C18: 39.14 | D18: 38.46 | E18: 38.8 | F18: 30342084 | G18: =E18-E17 -> 0.37 | H18: =G18/E17 -> 0.0096278949 | I18: =MAX(G18,0) -> 0.37 | J18: =MAX(-G18,0) -> 0 | K18: =(K17*13+I18)/14 -> 0.22076531 | L18: =(L17*13+J18)/14 -> 0.13265306 | M18: =IF(L18=0,100,100-100/(1+K18/MAX(L18,0.000001))) -> 62.465714 | Q18: =Q17+(2/13)*(E18-Q17) -> 37.710082 | V18: =IF(M18="","",IF(M18<Assumptions!$B$5,"BUY",IF(M18>Assumptions!$B$4,"SELL","HOLD"))) -> HOLD
A19: 45793 | B19: 39.01 | C19: 39.29 | D19: 38.99 | E19: 39.14 | F19: 39267060 | G19: =E19-E18 -> 0.34 | H19: =G19/E18 -> 0.0087628866 | I19: =MAX(G19,0) -> 0.34 | J19: =MAX(-G19,0) -> 0 | K19: =(K18*13+I19)/14 -> 0.22928207 | L19: =(L18*13+J19)/14 -> 0.12317784 | M19: =IF(L19=0,100,100-100/(1+K19/MAX(L19,0.000001))) -> 65.051957 | Q19: =Q18+(2/13)*(E19-Q18) -> 37.930069 | V19: =IF(M19="","",IF(M19<Assumptions!$B$5,"BUY",IF(M19>Assumptions!$B$4,"SELL","HOLD"))) -> HOLD
A20: 45796 | B20: 38.84 | C20: 38.96 | D20: 38.62 | E20: 38.79 | F20: 61002803 | G20: =E20-E19 -> -0.35 | H20: =G20/E19 -> -0.0089422586 | I20: =MAX(G20,0) -> 0 | J20: =MAX(-G20,0) -> 0.35 | K20: =(K19*13+I20)/14 -> 0.21290478 | L20: =(L19*13+J20)/14 -> 0.13937943 | M20: =IF(L20=0,100,100-100/(1+K20/MAX(L20,0.000001))) -> 60.435517 | Q20: =Q19+(2/13)*(E20-Q19) -> 38.062366 | V20: =IF(M20="","",IF(M20<Assumptions!$B$5,"BUY",IF(M20>Assumptions!$B$4,"SELL","HOLD"))) -> HOLD
A21: 45797 | B21: 39.44 | C21: 39.76 | D21: 39.24 | E21: 39.5 | F21: 51398156 | G21: =E21-E20 -> 0.71 | H21: =G21/E20 -> 0.018303687 | I21: =MAX(G21,0) -> 0.71 | J21: =MAX(-G21,0) -> 0 | K21: =(K20*13+I21)/14 -> 0.24841158 | L21: =(L20*13+J21)/14 -> 0.12942375 | M21: =IF(L21=0,100,100-100/(1+K21/MAX(L21,0.000001))) -> 65.74599 | Q21: =Q20+(2/13)*(E21-Q20) -> 38.283541 | V21: =IF(M21="","",IF(M21<Assumptions!$B$5,"BUY",IF(M21>Assumptions!$B$4,"SELL","HOLD"))) -> HOLD
A22: 45798 | B22: 40.6 | C22: 40.6 | D22: 40.34 | E22: 40.47 | F22: 65733869 | G22: =E22-E21 -> 0.97 | H22: =G22/E21 -> 0.024556962 | I22: =MAX(G22,0) -> 0.97 | J22: =MAX(-G22,0) -> 0 | K22: =(K21*13+I22)/14 -> 0.29995361 | L22: =(L21*13+J22)/14 -> 0.1201792 | M22: =IF(L22=0,100,100-100/(1+K22/MAX(L22,0.000001))) -> 71.39495 | N22: =AVERAGE(E3:E22) -> 37.7845 | Q22: =Q21+(2/13)*(E22-Q21) -> 38.619919 | V22: =IF(M22="","",IF(M22<Assumptions!$B$5,"BUY",IF(M22>Assumptions!$B$4,"SELL","HOLD"))) -> SELL
A23: 45799 | B23: 41.78 | C23: 41.95 | D23: 41.27 | E23: 41.61 | F23: 68502144 | G23: =E23-E22 -> 1.14 | H23: =G23/E22 -> 0.028169014 | I23: =MAX(G23,0) -> 1.14 | J23: =MAX(-G23,0) -> 0 | K23: =(K22*13+I23)/14 -> 0.35995692 | L23: =(L22*13+J23)/14 -> 0.11159497 | M23: =IF(L23=0,100,100-100/(1+K23/MAX(L23,0.000001))) -> 76.33453 | N23: =AVERAGE(E4:E23) -> 37.99 | Q23: =Q22+(2/13)*(E23-Q22) -> 39.079931 | V23: =IF(M23="","",IF(M23<Assumptions!$B$5,"BUY",IF(M23>Assumptions!$B$4,"SELL","HOLD"))) -> SELL
A24: 45800 | B24: 41.78 | C24: 42.08 | D24: 41.18 | E24: 41.63 | F24: 53726184 | G24: =E24-E23 -> 0.02 | H24: =G24/E23 -> 0.00048065369 | I24: =MAX(G24,0) -> 0.02 | J24: =MAX(-G24,0) -> 0 | K24: =(K23*13+I24)/14 -> 0.33567429 | L24: =(L23*13+J24)/14 -> 0.1036239 | M24: =IF(L24=0,100,100-100/(1+K24/MAX(L24,0.000001))) -> 76.411489 | N24: =AVERAGE(E5:E24) -> 38.184 | Q24: =Q23+(2/13)*(E24-Q23) -> 39.47225 | V24: =IF(M24="","",IF(M24<Assumptions!$B$5,"BUY",IF(M24>Assumptions!$B$4,"SELL","HOLD"))) -> SELL
A25: 45803 | B25: 41.81 | C25: 41.83 | D25: 41.81 | E25: 41.82 | F25: 42557703 | G25: =E25-E24 -> 0.19 | H25: =G25/E24 -> 0.0045640163 | I25: =MAX(G25,0) -> 0.19 | J25: =MAX(-G25,0) -> 0 | K25: =(K24*13+I25)/14 -> 0.32526898 | L25: =(L24*13+J25)/14 -> 0.096222193 | M25: =IF(L25=0,100,100-100/(1+K25/MAX(L25,0.000001))) -> 77.171006 | N25: =AVERAGE(E6:E25) -> 38.3705 | Q25: =Q24+(2/13)*(E25-Q24) -> 39.833442 | V25: =IF(M25="","",IF(M25<Assumptions!$B$5,"BUY",IF(M25>Assumptions!$B$4,"SELL","HOLD"))) -> SELL
A26: 45804 | B26: 42.18 | C26: 42.18 | D26: 41.96 | E26: 42.07 | F26: 23788751 | G26: =E26-E25 -> 0.25 | H26: =G26/E25 -> 0.005978001 | I26: =MAX(G26,0) -> 0.25 | J26: =MAX(-G26,0) -> 0 | K26: =(K25*13+I26)/14 -> 0.31989262 | L26: =(L25*13+J26)/14 -> 0.08934918 | M26: =IF(L26=0,100,100-100/(1+K26/MAX(L26,0.000001))) -> 78.167143 | N26: =AVERAGE(E7:E26) -> 38.593 | Q26: =Q25+(2/13)*(E26-Q25) -> 40.177528 | V26: =IF(M26="","",IF(M26<Assumptions!$B$5,"BUY",IF(M26>Assumptions!$B$4,"SELL","HOLD"))) -> SELL
A27: 45805 | B27: 42.01 | C27: 42.13 | D27: 42.01 | E27: 42.07 | F27: 33360951 | G27: =E27-E26 -> 0 | H27: =G27/E26 -> 0 | I27: =MAX(G27,0) -> 0 | J27: =MAX(-G27,0) -> 0 | K27: =(K26*13+I27)/14 -> 0.29704315 | L27: =(L26*13+J27)/14 -> 0.082967095 | M27: =IF(L27=0,100,100-100/(1+K27/MAX(L27,0.000001))) -> 78.167143 | N27: =AVERAGE(E8:E27) -> 38.835 | Q27: =Q26+(2/13)*(E27-Q26) -> 40.468677 | V27: =IF(M27="","",IF(M27<Assumptions!$B$5,"BUY",IF(M27>Assumptions!$B$4,"SELL","HOLD"))) -> SELL
A28: 45806 | B28: 42.38 | C28: 42.54 | D28: 42.34 | E28: 42.44 | F28: 38466858 | G28: =E28-E27 -> 0.37 | H28: =G28/E27 -> 0.0087948657 | I28: =MAX(G28,0) -> 0.37 | J28: =MAX(-G28,0) -> 0 | K28: =(K27*13+I28)/14 -> 0.30225436 | L28: =(L27*13+J28)/14 -> 0.077040874 | M28: =IF(L28=0,100,100-100/(1+K28/MAX(L28,0.000001))) -> 79.688415 | N28: =AVERAGE(E9:E28) -> 39.127 | Q28: =Q27+(2/13)*(E28-Q27) -> 40.771958 | R28: =AVERAGE(E3:E28) -> 38.743462 | S28: =Q28-R28 -> 2.0284963 | V28: =IF(M28="","",IF(M28<Assumptions!$B$5,"BUY",IF(M28>Assumptions!$B$4,"SELL","HOLD"))) -> SELL
A29: 45807 | B29: 42.42 | C29: 42.57 | D29: 42.17 | E29: 42.37 | F29: 49824330 | G29: =E29-E28 -> -0.07 | H29: =G29/E28 -> -0.0016493874 | I29: =MAX(G29,0) -> 0 | J29: =MAX(-G29,0) -> 0.07 | K29: =(K28*13+I29)/14 -> 0.28066476 | L29: =(L28*13+J29)/14 -> 0.076537955 | M29: =IF(L29=0,100,100-100/(1+K29/MAX(L29,0.000001))) -> 78.572964 | N29: =AVERAGE(E10:E29) -> 39.4195 | Q29: =Q28+(2/13)*(E29-Q28) -> 41.01781 | R29: =R28+(2/27)*(E29-R28) -> 39.012094 | S29: =Q29-R29 -> 2.0057165 | V29: =IF(M29="","",IF(M29<Assumptions!$B$5,"BUY",IF(M29>Assumptions!$B$4,"SELL","HOLD"))) -> SELL
A30: 45810 | B30: 42.12 | C30: 42.54 | D30: 41.98 | E30: 42.26 | F30: 46806136 | G30: =E30-E29 -> -0.11 | H30: =G30/E29 -> -0.0025961765 | I30: =MAX(G30,0) -> 0 | J30: =MAX(-G30,0) -> 0.11 | K30: =(K29*13+I30)/14 -> 0.26061728 | L30: =(L29*13+J30)/14 -> 0.078928101 | M30: =IF(L30=0,100,100-100/(1+K30/MAX(L30,0.000001))) -> 76.754771 | N30: =AVERAGE(E11:E30) -> 39.7095 | Q30: =Q29+(2/13)*(E30-Q29) -> 41.208917 | R30: =R29+(2/27)*(E30-R29) -> 39.25268 | S30: =Q30-R30 -> 1.9562369 | V30: =IF(M30="","",IF(M30<Assumptions!$B$5,"BUY",IF(M30>Assumptions!$B$4,"SELL","HOLD"))) -> SELL
A31: 45811 | B31: 43.21 | C31: 43.43 | D31: 43.21 | E31: 43.32 | F31: 58541865 | G31: =E31-E30 -> 1.06 | H31: =G31/E30 -> 0.025082821 | I31: =MAX(G31,0) -> 1.06 | J31: =MAX(-G31,0) -> 0 | K31: =(K30*13+I31)/14 -> 0.31771604 | L31: =(L30*13+J31)/14 -> 0.073290379 | M31: =IF(L31=0,100,100-100/(1+K31/MAX(L31,0.000001))) -> 81.255965 | N31: =AVERAGE(E12:E31) -> 40.048 | Q31: =Q30+(2/13)*(E31-Q30) -> 41.533699 | R31: =R30+(2/27)*(E31-R30) -> 39.553963 | S31: =Q31-R31 -> 1.979736 | V31: =IF(M31="","",IF(M31<Assumptions!$B$5,"BUY",IF(M31>Assumptions!$B$4,"SELL","HOLD"))) -> SELL
A32: 45812 | B32: 43.63 | C32: 43.63 | D32: 43.21 | E32: 43.42 | F32: 33532449 | G32: =E32-E31 -> 0.1 | H32: =G32/E31 -> 0.0023084026 | I32: =MAX(G32,0) -> 0.1 | J32: =MAX(-G32,0) -> 0 | K32: =(K31*13+I32)/14 -> 0.3021649 | L32: =(L31*13+J32)/14 -> 0.068055352 | M32: =IF(L32=0,100,100-100/(1+K32/MAX(L32,0.000001))) -> 81.617604 | N32: =AVERAGE(E13:E32) -> 40.41 | Q32: =Q31+(2/13)*(E32-Q31) -> 41.823899 | R32: =R31+(2/27)*(E32-R31) -> 39.840336 | S32: =Q32-R32 -> 1.9835631 | V32: =IF(M32="","",IF(M32<Assumptions!$B$5,"BUY",IF(M32>Assumptions!$B$4,"SELL","HOLD"))) -> SELL
A33: 45813 | B33: 43.5 | C33: 43.68 | D33: 43.26 | E33: 43.47 | F33: 34208333 | G33: =E33-E32 -> 0.05 | H33: =G33/E32 -> 0.0011515431 | I33: =MAX(G33,0) -> 0.05 | J33: =MAX(-G33,0) -> 0 | K33: =(K32*13+I33)/14 -> 0.28415312 | L33: =(L32*13+J33)/14 -> 0.063194256 | M33: =IF(L33=0,100,100-100/(1+K33/MAX(L33,0.000001))) -> 81.806612 | N33: =AVERAGE(E14:E33) -> 40.751 | Q33: =Q32+(2/13)*(E33-Q32) -> 42.077145 | R33: =R32+(2/27)*(E33-R32) -> 40.1092 | S33: =Q33-R33 -> 1.9679454 | V33: =IF(M33="","",IF(M33<Assumptions!$B$5,"BUY",IF(M33>Assumptions!$B$4,"SELL","HOLD"))) -> SELL
A34: 45814 | B34: 44.23 | C34: 44.23 | D34: 43.79 | E34: 44.01 | F34: 43216653 | G34: =E34-E33 -> 0.54 | H34: =G34/E33 -> 0.01242236 | I34: =MAX(G34,0) -> 0.54 | J34: =MAX(-G34,0) -> 0 | K34: =(K33*13+I34)/14 -> 0.30242789 | L34: =(L33*13+J34)/14 -> 0.05868038 | M34: =IF(L34=0,100,100-100/(1+K34/MAX(L34,0.000001))) -> 83.749921 | N34: =AVERAGE(E15:E34) -> 41.095 | Q34: =Q33+(2/13)*(E34-Q33) -> 42.374507 | R34: =R33+(2/27)*(E34-R33) -> 40.398148 | S34: =Q34-R34 -> 1.9763595 | V34: =IF(M34="","",IF(M34<Assumptions!$B$5,"BUY",IF(M34>Assumptions!$B$4,"SELL","HOLD"))) -> SELL
A35: 45817 | B35: 44.06 | C35: 44.16 | D35: 44.06 | E35: 44.11 | F35: 49999494 | G35: =E35-E34 -> 0.1 | H35: =G35/E34 -> 0.0022722109 | I35: =MAX(G35,0) -> 0.1 | J35: =MAX(-G35,0) -> 0 | K35: =(K34*13+I35)/14 -> 0.28796876 | L35: =(L34*13+J35)/14 -> 0.054488924 | M35: =IF(L35=0,100,100-100/(1+K35/MAX(L35,0.000001))) -> 84.088859 | N35: =AVERAGE(E16:E35) -> 41.403 | Q35: =Q34+(2/13)*(E35-Q34) -> 42.641506 | R35: =R34+(2/27)*(E35-R34) -> 40.6731 | S35: =Q35-R35 -> 1.9684063 | V35: =IF(M35="","",IF(M35<Assumptions!$B$5,"BUY",IF(M35>Assumptions!$B$4,"SELL","HOLD"))) -> SELL
A36: 45818 | B36: 44.45 | C36: 44.67 | D36: 43.91 | E36: 44.29 | F36: 34176063 | G36: =E36-E35 -> 0.18 | H36: =G36/E35 -> 0.0040807073 | I36: =MAX(G36,0) -> 0.18 | J36: =MAX(-G36,0) -> 0 | K36: =(K35*13+I36)/14 -> 0.28025671 | L36: =(L35*13+J36)/14 -> 0.050596858 | M36: =IF(L36=0,100,100-100/(1+K36/MAX(L36,0.000001))) -> 84.707174 | N36: =AVERAGE(E17:E36) -> 41.701 | Q36: =Q35+(2/13)*(E36-Q35) -> 42.895121 | R36: =R35+(2/27)*(E36-R35) -> 40.941018 | S36: =Q36-R36 -> 1.9541022 | T36: =AVERAGE(S28:S36) -> 1.9800625 | U36: =S36-T36 -> -0.025960224 | V36: =IF(M36="","",IF(M36<Assumptions!$B$5,"BUY",IF(M36>Assumptions!$B$4,"SELL","HOLD"))) -> SELL | X36: =IF(T36="","",IF(S36>T36,"BUY","SELL")) -> SELL
A37: 45819 | B37: 44.47 | C37: 44.67 | D37: 43.85 | E37: 44.26 | F37: 58511445 | G37: =E37-E36 -> -0.03 | H37: =G37/E36 -> -0.0006773538 | I37: =MAX(G37,0) -> 0 | J37: =MAX(-G37,0) -> 0.03 | K37: =(K36*13+I37)/14 -> 0.26023837 | L37: =(L36*13+J37)/14 -> 0.049125654 | M37: =IF(L37=0,100,100-100/(1+K37/MAX(L37,0.000001))) -> 84.120437 | N37: =AVERAGE(E18:E37) -> 41.9925 | Q37: =Q36+(2/13)*(E37-Q36) -> 43.105102 | R37: =R36+(2/27)*(E37-R36) -> 41.186869 | S37: =Q37-R37 -> 1.9182332 | T37: =T36+(2/10)*(S37-T36) -> 1.9676966 | U37: =S37-T37 -> -0.049463423 | V37: =IF(M37="","",IF(M37<Assumptions!$B$5,"BUY",IF(M37>Assumptions!$B$4,"SELL","HOLD"))) -> SELL | X37: =IF(T37="","",IF(S37>T37,"BUY","SELL")) -> SELL
A38: 45820 | B38: 43.52 | C38: 43.68 | D38: 43.34 | E38: 43.51 | F38: 36079346 | G38: =E38-E37 -> -0.75 | H38: =G38/E37 -> -0.016945323 | I38: =MAX(G38,0) -> 0 | J38: =MAX(-G38,0) -> 0.75 | K38: =(K37*13+I38)/14 -> 0.24164991 | L38: =(L37*13+J38)/14 -> 0.099188108 | M38: =IF(L38=0,100,100-100/(1+K38/MAX(L38,0.000001))) -> 70.898755 | N38: =AVERAGE(E19:E38) -> 42.228 | Q38: =Q37+(2/13)*(E38-Q37) -> 43.167394 | R38: =R37+(2/27)*(E38-R37) -> 41.358953 | S38: =Q38-R38 -> 1.8084414 | T38: =T37+(2/10)*(S38-T37) -> 1.9358456 | U38: =S38-T38 -> -0.12740418 | V38: =IF(M38="","",IF(M38<Assumptions!$B$5,"BUY",IF(M38>Assumptions!$B$4,"SELL","HOLD"))) -> SELL | X38: =IF(T38="","",IF(S38>T38,"BUY","SELL")) -> SELL
A39: 45821 | B39: 43.44 | C39: 43.62 | D39: 43.38 | E39: 43.5 | F39: 10888164 | G39: =E39-E38 -> -0.01 | H39: =G39/E38 -> -0.00022983222 | I39: =MAX(G39,0) -> 0 | J39: =MAX(-G39,0) -> 0.01 | K39: =(K38*13+I39)/14 -> 0.22438921 | L39: =(L38*13+J39)/14 -> 0.092817528 | M39: =IF(L39=0,100,100-100/(1+K39/MAX(L39,0.000001))) -> 70.739105 | N39: =AVERAGE(E20:E39) -> 42.446 | Q39: =Q38+(2/13)*(E39-Q38) -> 43.218564 | R39: =R38+(2/27)*(E39-R38) -> 41.517549 | S39: =Q39-R39 -> 1.7010154 | T39: =T38+(2/10)*(S39-T38) -> 1.8888795 | U39: =S39-T39 -> -0.18786411 | V39: =IF(M39="","",IF(M39<Assumptions!$B$5,"BUY",IF(M39>Assumptions!$B$4,"SELL","HOLD"))) -> SELL | X39: =IF(T39="","",IF(S39>T39,"BUY","SELL")) -> SELL
A40: 45824 | B40: 42.85 | C40: 43.06 | D40: 42.58 | E40: 42.82 | F40: 68873453 | G40: =E40-E39 -> -0.68 | H40: =G40/E39 -> -0.015632184 | I40: =MAX(G40,0) -> 0 | J40: =MAX(-G40,0) -> 0.68 | K40: =(K39*13+I40)/14 -> 0.20836141 | L40: =(L39*13+J40)/14 -> 0.13475913 | M40: =IF(L40=0,100,100-100/(1+K40/MAX(L40,0.000001))) -> 60.725425 | N40: =AVERAGE(E21:E40) -> 42.6475 | Q40: =Q39+(2/13)*(E40-Q39) -> 43.157247 | R40: =R39+(2/27)*(E40-R39) -> 41.614027 | S40: =Q40-R40 -> 1.54322 | T40: =T39+(2/10)*(S40-T39) -> 1.8197476 | U40: =S40-T40 -> -0.27652764 | V40: =IF(M40="","",IF(M40<Assumptions!$B$5,"BUY",IF(M40>Assumptions!$B$4,"SELL","HOLD"))) -> HOLD | X40: =IF(T40="","",IF(S40>T40,"BUY","SELL")) -> SELL
...

Sheet KBANK
A1: Thai SET Trading Model | KBANK | Rule-Based Buy/Sell Signals
A2: Date | B2: Open | C2: High | D2: Low | E2: Close (THB) | F2: Volume | G2: Change | H2: % Change | I2: Gain | J2: Loss | K2: Avg Gain 14 | L2: Avg Loss 14 | M2: RSI (14) | N2: SMA 20 | O2: SMA 50 | P2: SMA 200 | Q2: EMA 12 | R2: EMA 26 | S2: MACD Line | T2: Signal Line | U2: Histogram | V2: RSI Signal | W2: MA Signal | X2: MACD Signal | Y2: Score | Z2: OVERALL
A3: 45771 | B3: 148.47 | C3: 148.7 | D3: 147.3 | E3: 148 | F3: 4373172
A4: 45772 | B4: 148.34 | C4: 148.87 | D4: 147.91 | E4: 148.39 | F4: 7623155 | G4: =E4-E3 -> 0.39 | H4: =G4/E3 -> 0.0026351351 | I4: =MAX(G4,0) -> 0.39 | J4: =MAX(-G4,0) -> 0
A5: 45775 | B5: 146.93 | C5: 148.7 | D5: 144.84 | E5: 146.77 | F5: 15475143 | G5: =E5-E4 -> -1.62 | H5: =G5/E4 -> -0.010917178 | I5: =MAX(G5,0) -> 0 | J5: =MAX(-G5,0) -> 1.62
A6: 45776 | B6: 145.51 | C6: 148.1 | D6: 143.6 | E6: 145.85 | F6: 10333481 | G6: =E6-E5 -> -0.92 | H6: =G6/E5 -> -0.006268311 | I6: =MAX(G6,0) -> 0 | J6: =MAX(-G6,0) -> 0.92
A7: 45777 | B7: 145.65 | C7: 147.72 | D7: 145.1 | E7: 146.41 | F7: 12310655 | G7: =E7-E6 -> 0.56 | H7: =G7/E6 -> 0.0038395612 | I7: =MAX(G7,0) -> 0.56 | J7: =MAX(-G7,0) -> 0
A8: 45778 | B8: 144.21 | C8: 144.21 | D8: 144.13 | E8: 144.17 | F8: 13702641 | G8: =E8-E7 -> -2.24 | H8: =G8/E7 -> -0.015299501 | I8: =MAX(G8,0) -> 0 | J8: =MAX(-G8,0) -> 2.24
A9: 45779 | B9: 146.97 | C9: 147.2 | D9: 145.6 | E9: 146.4 | F9: 15549627 | G9: =E9-E8 -> 2.23 | H9: =G9/E8 -> 0.01546785 | I9: =MAX(G9,0) -> 2.23 | J9: =MAX(-G9,0) -> 0
A10: 45782 | B10: 142.42 | C10: 143.71 | D10: 141.91 | E10: 142.81 | F10: 9791608 | G10: =E10-E9 -> -3.59 | H10: =G10/E9 -> -0.024521858 | I10: =MAX(G10,0) -> 0 | J10: =MAX(-G10,0) -> 3.59
A11: 45783 | B11: 144.03 | C11: 144.41 | D11: 142.43 | E11: 143.42 | F11: 10639860 | G11: =E11-E10 -> 0.61 | H11: =G11/E10 -> 0.0042714096 | I11: =MAX(G11,0) -> 0.61 | J11: =MAX(-G11,0) -> 0
A12: 45784 | B12: 142.28 | C12: 142.76 | D12: 142.28 | E12: 142.52 | F12: 10342936 | G12: =E12-E11 -> -0.9 | H12: =G12/E11 -> -0.0062752754 | I12: =MAX(G12,0) -> 0 | J12: =MAX(-G12,0) -> 0.9
A13: 45785 | B13: 145.76 | C13: 146.61 | D13: 144.03 | E13: 145.32 | F13: 5206931 | G13: =E13-E12 -> 2.8 | H13: =G13/E12 -> 0.019646365 | I13: =MAX(G13,0) -> 2.8 | J13: =MAX(-G13,0) -> 0
A14: 45786 | B14: 147.15 | C14: 147.65 | D14: 145.91 | E14: 146.78 | F14: 9907887 | G14: =E14-E13 -> 1.46 | H14: =G14/E13 -> 0.010046793 | I14: =MAX(G14,0) -> 1.46 | J14: =MAX(-G14,0) -> 0 | Q14: =AVERAGE(E3:E14) -> 145.57
A15: 45789 | B15: 142.4 | C15: 143.34 | D15: 142.4 | E15: 142.87 | F15: 6409509 | G15: =E15-E14 -> -3.91 | H15: =G15/E14 -> -0.026638507 | I15: =MAX(G15,0) -> 0 | J15: =MAX(-G15,0) -> 3.91 | Q15: =Q14+(2/13)*(E15-Q14) -> 145.15462
A16: 45790 | B16: 138.37 | C16: 138.53 | D16: 138.37 | E16: 138.45 | F16: 16789587 | G16: =E16-E15 -> -4.42 | H16: =G16/E15 -> -0.030937216 | I16: =MAX(G16,0) -> 0 | J16: =MAX(-G16,0) -> 4.42 | Q16: =Q15+(2/13)*(E16-Q15) -> 144.12314
A17: 45791 | B17: 136.62 | C17: 136.72 | D17: 136.62 | E17: 136.67 | F17: 14913983 | G17: =E17-E16 -> -1.78 | H17: =G17/E16 -> -0.012856627 | I17: =MAX(G17,0) -> 0 | J17: =MAX(-G17,0) -> 1.78 | K17: =AVERAGE(I4:I17) -> 0.575 | L17: =AVERAGE(J4:J17) -> 1.3842857 | M17: =IF(L17=0,100,100-100/(1+K17/MAX(L17,0.000001))) -> 29.34743 | Q17: =Q16+(2/13)*(E17-Q16) -> 142.9765 | V17: =IF(M17="","",IF(M17<Assumptions!$B$5,"BUY",IF(M17>Assumptions!$B$4,"SELL","HOLD"))) -> BUY
A18: 45792 | B18: 135.39 | C18: 136.89 | D18: 134.69 | E18: 135.79 | F18: 4849181 | G18: =E18-E17 -> -0.88 | H18: =G18/E17 -> -0.0064388673 | I18: =MAX(G18,0) -> 0 | J18: =MAX(-G18,0) -> 0.88 | K18: =(K17*13+I18)/14 -> 0.53392857 | L18: =(L17*13+J18)/14 -> 1.3482653 | M18: =IF(L18=0,100,100-100/(1+K18/MAX(L18,0.000001))) -> 28.367352 | Q18: =Q17+(2/13)*(E18-Q17) -> 141.87088 | V18: =IF(M18="","",IF(M18<Assumptions!$B$5,"BUY",IF(M18>Assumptions!$B$4,"SELL","HOLD"))) -> BUY
A19: 45793 | B19: 135.08 | C19: 135.86 | D19: 135.08 | E19: 135.47 | F19: 18894794 | G19: =E19-E18 -> -0.32 | H19: =G19/E18 -> -0.00235658 | I19: =MAX(G19,0) -> 0 | J19: =MAX(-G19,0) -> 0.32 | K19: =(K18*13+I19)/14 -> 0.49579082 | L19: =(L18*13+J19)/14 -> 1.2748178 | M19: =IF(L19=0,100,100-100/(1+K19/MAX(L19,0.000001))) -> 28.001153 | Q19: =Q18+(2/13)*(E19-Q18) -> 140.88613 | V19: =IF(M19="","",IF(M19<Assumptions!$B$5,"BUY",IF(M19>Assumptions!$B$4,"SELL","HOLD"))) -> BUY
A20: 45796 | B20: 135.36 | C20: 136.67 | D20: 134.41 | E20: 135.54 | F20: 18188790 | G20: =E20-E19 -> 0.07 | H20: =G20/E19 -> 0.00051671957 | I20: =MAX(G20,0) -> 0.07 | J20: =MAX(-G20,0) -> 0 | K20: =(K19*13+I20)/14 -> 0.46537719 | L20: =(L19*13+J20)/14 -> 1.1837594 | M20: =IF(L20=0,100,100-100/(1+K20/MAX(L20,0.000001))) -> 28.219445 | Q20: =Q19+(2/13)*(E20-Q19) -> 140.06365 | V20: =IF(M20="","",IF(M20<Assumptions!$B$5,"BUY",IF(M20>Assumptions!$B$4,"SELL","HOLD"))) -> BUY
A21: 45797 | B21: 136.47 | C21: 137.46 | D21: 136.04 | E21: 136.75 | F21: 8711131 | G21: =E21-E20 -> 1.21 | H21: =G21/E20 -> 0.0089272539 | I21: =MAX(G21,0) -> 1.21 | J21: =MAX(-G21,0) -> 0 | K21: =(K20*13+I21)/14 -> 0.51856453 | L21: =(L20*13+J21)/14 -> 1.0992051 | M21: =IF(L21=0,100,100-100/(1+K21/MAX(L21,0.000001))) -> 32.054287 | Q21: =Q20+(2/13)*(E21-Q20) -> 139.55386 | V21: =IF(M21="","",IF(M21<Assumptions!$B$5,"BUY",IF(M21>Assumptions!$B$4,"SELL","HOLD"))) -> HOLD
A22: 45798 | B22: 134.23 | C22: 134.51 | D22: 134.21 | E22: 134.36 | F22: 18284873 | G22: =E22-E21 -> -2.39 | H22: =G22/E21 -> -0.017477148 | I22: =MAX(G22,0) -> 0 | J22: =MAX(-G22,0) -> 2.39 | K22: =(K21*13+I22)/14 -> 0.48152421 | L22: =(L21*13+J22)/14 -> 1.1914048 | M22: =IF(L22=0,100,100-100/(1+K22/MAX(L22,0.000001))) -> 28.783303 | N22: =AVERAGE(E3:E22) -> 142.137 | Q22: =Q21+(2/13)*(E22-Q21) -> 138.7548 | V22: =IF(M22="","",IF(M22<Assumptions!$B$5,"BUY",IF(M22>Assumptions!$B$4,"SELL","HOLD"))) -> BUY
A23: 45799 | B23: 131.14 | C23: 131.38 | D23: 131.14 | E23: 131.26 | F23: 16140246 | G23: =E23-E22 -> -3.1 | H23: =G23/E22 -> -0.023072343 | I23: =MAX(G23,0) -> 0 | J23: =MAX(-G23,0) -> 3.1 | K23: =(K22*13+I23)/14 -> 0.44712962 | L23: =(L22*13+J23)/14 -> 1.327733 | M23: =IF(L23=0,100,100-100/(1+K23/MAX(L23,0.000001))) -> 25.192351 | N23: =AVERAGE(E4:E23) -> 141.3 | Q23: =Q22+(2/13)*(E23-Q22) -> 137.60176 | V23: =IF(M23="","",IF(M23<Assumptions!$B$5,"BUY",IF(M23>Assumptions!$B$4,"SELL","HOLD"))) -> BUY
A24: 45800 | B24: 131.58 | C24: 132.52 | D24: 130.88 | E24: 131.7 | F24: 15242925 | G24: =E24-E23 -> 0.44 | H24: =G24/E23 -> 0.0033521256 | I24: =MAX(G24,0) -> 0.44 | J24: =MAX(-G24,0) -> 0 | K24: =(K23*13+I24)/14 -> 0.44662036 | L24: =(L23*13+J24)/14 -> 1.2328949 | M24: =IF(L24=0,100,100-100/(1+K24/MAX(L24,0.000001))) -> 26.592218 | N24: =AVERAGE(E5:E24) -> 140.4655 | Q24: =Q23+(2/13)*(E24-Q23) -> 136.69379 | V24: =IF(M24="","",IF(M24<Assumptions!$B$5,"BUY",IF(M24>Assumptions!$B$4,"SELL","HOLD"))) -> BUY
A25: 45803 | B25: 131.06 | C25: 131.14 | D25: 131.06 | E25: 131.1 | F25: 11659486 | G25: =E25-E24 -> -0.6 | H25: =G25/E24 -> -0.0045558087 | I25: =MAX(G25,0) -> 0 | J25: =MAX(-G25,0) -> 0.6 | K25: =(K24*13+I25)/14 -> 0.41471891 | L25: =(L24*13+J25)/14 -> 1.1876881 | M25: =IF(L25=0,100,100-100/(1+K25/MAX(L25,0.000001))) -> 25.880996 | N25: =AVERAGE(E6:E25) -> 139.682 | Q25: =Q24+(2/13)*(E25-Q24) -> 135.83321 | V25: =IF(M25="","",IF(M25<Assumptions!$B$5,"BUY",IF(M25>Assumptions!$B$4,"SELL","HOLD"))) -> BUY
A26: 45804 | B26: 130.61 | C26: 131.84 | D26: 130.04 | E26: 130.94 | F26: 8056629 | G26: =E26-E25 -> -0.16 | H26: =G26/E25 -> -0.0012204424 | I26: =MAX(G26,0) -> 0 | J26: =MAX(-G26,0) -> 0.16 | K26: =(K25*13+I26)/14 -> 0.38509613 | L26: =(L25*13+J26)/14 -> 1.1142818 | M26: =IF(L26=0,100,100-100/(1+K26/MAX(L26,0.000001))) -> 25.683726 | N26: =AVERAGE(E7:E26) -> 138.9365 | Q26: =Q25+(2/13)*(E26-Q25) -> 135.08041 | V26: =IF(M26="","",IF(M26<Assumptions!$B$5,"BUY",IF(M26>Assumptions!$B$4,"SELL","HOLD"))) -> BUY
A27: 45805 | B27: 129.96 | C27: 130.12 | D27: 129.6 | E27: 129.86 | F27: 6457346 | G27: =E27-E26 -> -1.08 | H27: =G27/E26 -> -0.0082480525 | I27: =MAX(G27,0) -> 0 | J27: =MAX(-G27,0) -> 1.08 | K27: =(K26*13+I27)/14 -> 0.35758926 | L27: =(L26*13+J27)/14 -> 1.1118331 | M27: =IF(L27=0,100,100-100/(1+K27/MAX(L27,0.000001))) -> 24.335362 | N27: =AVERAGE(E8:E27) -> 138.109 | Q27: =Q26+(2/13)*(E27-Q26) -> 134.27727 | V27: =IF(M27="","",IF(M27<Assumptions!$B$5,"BUY",IF(M27>Assumptions!$B$4,"SELL","HOLD"))) -> BUY
A28: 45806 | B28: 129.58 | C28: 130.3 | D28: 128.86 | E28: 129.58 | F28: 13950345 | G28: =E28-E27 -> -0.28 | H28: =G28/E27 -> -0.0021561682 | I28: =MAX(G28,0) -> 0 | J28: =MAX(-G28,0) -> 0.28 | K28: =(K27*13+I28)/14 -> 0.33204717 | L28: =(L27*13+J28)/14 -> 1.0524165 | M28: =IF(L28=0,100,100-100/(1+K28/MAX(L28,0.000001))) -> 23.983813 | N28: =AVERAGE(E9:E28) -> 137.3795 | Q28: =Q27+(2/13)*(E28-Q27) -> 133.55461 | R28: =AVERAGE(E3:E28) -> 139.50692 | S28: =Q28-R28 -> -5.9523109 | V28: =IF(M28="","",IF(M28<Assumptions!$B$5,"BUY",IF(M28>Assumptions!$B$4,"SELL","HOLD"))) -> BUY
A29: 45807 | B29: 132.06 | C29: 132.18 | D29: 132.06 | E29: 132.12 | F29: 17405000 | G29: =E29-E28 -> 2.54 | H29: =G29/E28 -> 0.01960179 | I29: =MAX(G29,0) -> 2.54 | J29: =MAX(-G29,0) -> 0 | K29: =(K28*13+I29)/14 -> 0.48975809 | L29: =(L28*13+J29)/14 -> 0.97724388 | M29: =IF(L29=0,100,100-100/(1+K29/MAX(L29,0.000001))) -> 33.384965 | N29: =AVERAGE(E10:E29) -> 136.6655 | Q29: =Q28+(2/13)*(E29-Q28) -> 133.3339 | R29: =R28+(2/27)*(E29-R28) -> 138.95974 | S29: =Q29-R29 -> -5.6258409 | V29: =IF(M29="","",IF(M29<Assumptions!$B$5,"BUY",IF(M29>Assumptions!$B$4,"SELL","HOLD"))) -> HOLD
A30: 45810 | B30: 130.19 | C30: 130.75 | D30: 127.99 | E30: 129.37 | F30: 14285236 | G30: =E30-E29 -> -2.75 | H30: =G30/E29 -> -0.020814411 | I30: =MAX(G30,0) -> 0 | J30: =MAX(-G30,0) -> 2.75 | K30: =(K29*13+I30)/14 -> 0.45477537 | L30: =(L29*13+J30)/14 -> 1.1038693 | M30: =IF(L30=0,100,100-100/(1+K30/MAX(L30,0.000001))) -> 29.177616 | N30: =AVERAGE(E11:E30) -> 135.9935 | Q30: =Q29+(2/13)*(E30-Q29) -> 132.72407 | R30: =R29+(2/27)*(E30-R29) -> 138.24939 | S30: =Q30-R30 -> -5.5253207 | V30: =IF(M30="","",IF(M30<Assumptions!$B$5,"BUY",IF(M30>Assumptions!$B$4,"SELL","HOLD"))) -> BUY
A31: 45811 | B31: 127.01 | C31: 127.85 | D31: 126.83 | E31: 127.34 | F31: 12792030 | G31: =E31-E30 -> -2.03 | H31: =G31/E30 -> -0.015691428 | I31: =MAX(G31,0) -> 0 | J31: =MAX(-G31,0) -> 2.03 | K31: =(K30*13+I31)/14 -> 0.42229141 | L31: =(L30*13+J31)/14 -> 1.1700215 | M31: =IF(L31=0,100,100-100/(1+K31/MAX(L31,0.000001))) -> 26.52063 | N31: =AVERAGE(E12:E31) -> 135.1895 | Q31: =Q30+(2/13)*(E31-Q30) -> 131.89575 | R31: =R30+(2/27)*(E31-R30) -> 137.44129 | S31: =Q31-R31 -> -5.5455363 | V31: =IF(M31="","",IF(M31<Assumptions!$B$5,"BUY",IF(M31>Assumptions!$B$4,"SELL","HOLD"))) -> BUY
A32: 45812 | B32: 128.48 | C32: 129.29 | D32: 127.55 | E32: 128.42 | F32: 5995289 | G32: =E32-E31 -> 1.08 | H32: =G32/E31 -> 0.0084812313 | I32: =MAX(G32,0) -> 1.08 | J32: =MAX(-G32,0) -> 0 | K32: =(K31*13+I32)/14 -> 0.4692706 | L32: =(L31*13+J32)/14 -> 1.0864485 | M32: =IF(L32=0,100,100-100/(1+K32/MAX(L32,0.000001))) -> 30.164223 | N32: =AVERAGE(E13:E32) -> 134.4845 | Q32: =Q31+(2/13)*(E32-Q31) -> 131.36102 | R32: =R31+(2/27)*(E32-R31) -> 136.77305 | S32: =Q32-R32 -> -5.4120239 | V32: =IF(M32="","",IF(M32<Assumptions!$B$5,"BUY",IF(M32>Assumptions!$B$4,"SELL","HOLD"))) -> HOLD
A33: 45813 | B33: 130.89 | C33: 131.54 | D33: 130.62 | E33: 131.08 | F33: 15221689 | G33: =E33-E32 -> 2.66 | H33: =G33/E32 -> 0.020713285 | I33: =MAX(G33,0) -> 2.66 | J33: =MAX(-G33,0) -> 0 | K33: =(K32*13+I33)/14 -> 0.62575127 | L33: =(L32*13+J33)/14 -> 1.0088451 | M33: =IF(L33=0,100,100-100/(1+K33/MAX(L33,0.000001))) -> 38.2817 | N33: =AVERAGE(E14:E33) -> 133.7725 | Q33: =Q32+(2/13)*(E33-Q32) -> 131.31779 | R33: =R32+(2/27)*(E33-R32) -> 136.35134 | S33: =Q33-R33 -> -5.0335509 | V33: =IF(M33="","",IF(M33<Assumptions!$B$5,"BUY",IF(M33>Assumptions!$B$4,"SELL","HOLD"))) -> HOLD
A34: 45814 | B34: 130.6 | C34: 130.88 | D34: 130.6 | E34: 130.74 | F34: 15541969 | G34: =E34-E33 -> -0.34 | H34: =G34/E33 -> -0.0025938358 | I34: =MAX(G34,0) -> 0 | J34: =MAX(-G34,0) -> 0.34 | K34: =(K33*13+I34)/14 -> 0.58105475 | L34: =(L33*13+J34)/14 -> 0.96107043 | M34: =IF(L34=0,100,100-100/(1+K34/MAX(L34,0.000001))) -> 37.678832 | N34: =AVERAGE(E15:E34) -> 132.9705 | Q34: =Q33+(2/13)*(E34-Q33) -> 131.2289 | R34: =R33+(2/27)*(E34-R33) -> 135.93568 | S34: =Q34-R34 -> -4.7067866 | V34: =IF(M34="","",IF(M34<Assumptions!$B$5,"BUY",IF(M34>Assumptions!$B$4,"SELL","HOLD"))) -> HOLD
A35: 45817 | B35: 128.48 | C35: 129.53 | D35: 127.71 | E35: 128.62 | F35: 9742314 | G35: =E35-E34 -> -2.12 | H35: =G35/E34 -> -0.016215389 | I35: =MAX(G35,0) -> 0 | J35: =MAX(-G35,0) -> 2.12 | K35: =(K34*13+I35)/14 -> 0.53955084 | L35: =(L34*13+J35)/14 -> 1.0438511 | M35: =IF(L35=0,100,100-100/(1+K35/MAX(L35,0.000001))) -> 34.075418 | N35: =AVERAGE(E16:E35) -> 132.258 | Q35: =Q34+(2/13)*(E35-Q34) -> 130.82753 | R35: =R34+(2/27)*(E35-R34) -> 135.39378 | S35: =Q35-R35 -> -4.5662529 | V35: =IF(M35="","",IF(M35<Assumptions!$B$5,"BUY",IF(M35>Assumptions!$B$4,"SELL","HOLD"))) -> HOLD
A36: 45818 | B36: 125.29 | C36: 125.89 | D36: 124.77 | E36: 125.33 | F36: 13134078 | G36: =E36-E35 -> -3.29 | H36: =G36/E35 -> -0.025579226 | I36: =MAX(G36,0) -> 0 | J36: =MAX(-G36,0) -> 3.29 | K36: =(K35*13+I36)/14 -> 0.50101149 | L36: =(L35*13+J36)/14 -> 1.2042903 | M36: =IF(L36=0,100,100-100/(1+K36/MAX(L36,0.000001))) -> 29.379638 | N36: =AVERAGE(E17:E36) -> 131.602 | Q36: =Q35+(2/13)*(E36-Q35) -> 129.98175 | R36: =R35+(2/27)*(E36-R35) -> 134.64832 | S36: =Q36-R36 -> -4.6665612 | T36: =AVERAGE(S28:S36) -> -5.2260205 | U36: =S36-T36 -> 0.55945929 | V36: =IF(M36="","",IF(M36<Assumptions!$B$5,"BUY",IF(M36>Assumptions!$B$4,"SELL","HOLD"))) -> BUY | X36: =IF(T36="","",IF(S36>T36,"BUY","SELL")) -> BUY
A37: 45819 | B37: 125.37 | C37: 126.17 | D37: 125.37 | E37: 125.77 | F37: 8109463 | G37: =E37-E36 -> 0.44 | H37: =G37/E36 -> 0.0035107317 | I37: =MAX(G37,0) -> 0.44 | J37: =MAX(-G37,0) -> 0 | K37: =(K36*13+I37)/14 -> 0.49665353 | L37: =(L36*13+J37)/14 -> 1.1182696 | M37: =IF(L37=0,100,100-100/(1+K37/MAX(L37,0.000001))) -> 30.754005 | N37: =AVERAGE(E18:E37) -> 131.057 | Q37: =Q36+(2/13)*(E37-Q36) -> 129.33379 | R37: =R36+(2/27)*(E37-R36) -> 133.99066 | S37: =Q37-R37 -> -4.6568704 | T37: =T36+(2/10)*(S37-T36) -> -5.1121905 | U37: =S37-T37 -> 0.45532004 | V37: =IF(M37="","",IF(M37<Assumptions!$B$5,"BUY",IF(M37>Assumptions!$B$4,"SELL","HOLD"))) -> HOLD | X37: =IF(T37="","",IF(S37>T37,"BUY","SELL")) -> BUY
A38: 45820 | B38: 123.85 | C38: 123.85 | D38: 123.67 | E38: 123.76 | F38: 14404868 | G38: =E38-E37 -> -2.01 | H38: =G38/E37 -> -0.015981554 | I38: =MAX(G38,0) -> 0 | J38: =MAX(-G38,0) -> 2.01 | K38: =(K37*13+I38)/14 -> 0.46117828 | L38: =(L37*13+J38)/14 -> 1.1819646 | M38: =IF(L38=0,100,100-100/(1+K38/MAX(L38,0.000001))) -> 28.066839 | N38: =AVERAGE(E19:E38) -> 130.4555 | Q38: =Q37+(2/13)*(E38-Q37) -> 128.47629 | R38: =R37+(2/27)*(E38-R37) -> 133.23284 | S38: =Q38-R38 -> -4.7565501 | T38: =T37+(2/10)*(S38-T37) -> -5.0410624 | U38: =S38-T38 -> 0.28451231 | V38: =IF(M38="","",IF(M38<Assumptions!$B$5,"BUY",IF(M38>Assumptions!$B$4,"SELL","HOLD"))) -> BUY | X38: =IF(T38="","",IF(S38>T38,"BUY","SELL")) -> BUY
A39: 45821 | B39: 127.21 | C39: 128.32 | D39: 126.32 | E39: 127.32 | F39: 12422857 | G39: =E39-E38 -> 3.56 | H39: =G39/E38 -> 0.028765352 | I39: =MAX(G39,0) -> 3.56 | J39: =MAX(-G39,0) -> 0 | K39: =(K38*13+I39)/14 -> 0.68252269 | L39: =(L38*13+J39)/14 -> 1.0975386 | M39: =IF(L39=0,100,100-100/(1+K39/MAX(L39,0.000001))) -> 38.342652 | N39: =AVERAGE(E20:E39) -> 130.048 | Q39: =Q38+(2/13)*(E39-Q38) -> 128.2984 | R39: =R38+(2/27)*(E39-R38) -> 132.79485 | S39: =Q39-R39 -> -4.4964524 | T39: =T38+(2/10)*(S39-T38) -> -4.9321404 | U39: =S39-T39 -> 0.43568801 | V39: =IF(M39="","",IF(M39<Assumptions!$B$5,"BUY",IF(M39>Assumptions!$B$4,"SELL","HOLD"))) -> HOLD | X39: =IF(T39="","",IF(S39>T39,"BUY","SELL")) -> BUY
A40: 45824 | B40: 131.04 | C40: 131.66 | D40: 130.88 | E40: 131.27 | F40: 8512165 | G40: =E40-E39 -> 3.95 | H40: =G40/E39 -> 0.031024191 | I40: =MAX(G40,0) -> 3.95 | J40: =MAX(-G40,0) -> 0 | K40: =(K39*13+I40)/14 -> 0.91591392 | L40: =(L39*13+J40)/14 -> 1.019143 | M40: =IF(L40=0,100,100-100/(1+K40/MAX(L40,0.000001))) -> 47.332661 | N40: =AVERAGE(E21:E40) -> 129.8345 | Q40: =Q39+(2/13)*(E40-Q39) -> 128.75557 | R40: =R39+(2/27)*(E40-R39) -> 132.6819 | S40: =Q40-R40 -> -3.9263308 | T40: =T39+(2/10)*(S40-T39) -> -4.7309785 | U40: =S40-T40 -> 0.80464769 | V40: =IF(M40="","",IF(M40<Assumptions!$B$5,"BUY",IF(M40>Assumptions!$B$4,"SELL","HOLD"))) -> HOLD | X40: =IF(T40="","",IF(S40>T40,"BUY","SELL")) -> BUY
...

Sheet AOT
A1: Thai SET Trading Model | AOT | Rule-Based Buy/Sell Signals
A2: Date | B2: Open | C2: High | D2: Low | E2: Close (THB) | F2: Volume | G2: Change | H2: % Change | I2: Gain | J2: Loss | K2: Avg Gain 14 | L2: Avg Loss 14 | M2: RSI (14) | N2: SMA 20 | O2: SMA 50 | P2: SMA 200 | Q2: EMA 12 | R2: EMA 26 | S2: MACD Line | T2: Signal Line | U2: Histogram | V2: RSI Signal | W2: MA Signal | X2: MACD Signal | Y2: Score | Z2: OVERALL
A3: 45771 | B3: 68.65 | C3: 68.72 | D3: 68.28 | E3: 68.5 | F3: 30321209
A4: 45772 | B4: 68.46 | C4: 68.94 | D4: 67.64 | E4: 68.29 | F4: 37053243 | G4: =E4-E3 -> -0.21 | H4: =G4/E3 -> -0.0030656934 | I4: =MAX(G4,0) -> 0 | J4: =MAX(-G4,0) -> 0.21
A5: 45775 | B5: 68.85 | C5: 68.85 | D5: 68.67 | E5: 68.76 | F5: 16123859 | G5: =E5-E4 -> 0.47 | H5: =G5/E4 -> 0.0068824132 | I5: =MAX(G5,0) -> 0.47 | J5: =MAX(-G5,0) -> 0
A6: 45776 | B6: 68.21 | C6: 68.91 | D6: 67.85 | E6: 68.38 | F6: 39432982 | G6: =E6-E5 -> -0.38 | H6: =G6/E5 -> -0.0055264689 | I6: =MAX(G6,0) -> 0 | J6: =MAX(-G6,0) -> 0.38
A7: 45777 | B7: 69.11 | C7: 69.11 | D7: 68.79 | E7: 68.95 | F7: 20332588 | G7: =E7-E6 -> 0.57 | H7: =G7/E6 -> 0.0083357707 | I7: =MAX(G7,0) -> 0.57 | J7: =MAX(-G7,0) -> 0
A8: 45778 | B8: 68.83 | C8: 70.16 | D8: 68.6 | E8: 69.38 | F8: 28231536 | G8: =E8-E7 -> 0.43 | H8: =G8/E7 -> 0.0062364032 | I8: =MAX(G8,0) -> 0.43 | J8: =MAX(-G8,0) -> 0
A9: 45779 | B9: 69.64 | C9: 70.85 | D9: 69.11 | E9: 69.98 | F9: 41554942 | G9: =E9-E8 -> 0.6 | H9: =G9/E8 -> 0.0086480254 | I9: =MAX(G9,0) -> 0.6 | J9: =MAX(-G9,0) -> 0
A10: 45782 | B10: 71.12 | C10: 71.9 | D10: 71.12 | E10: 71.51 | F10: 24947233 | G10: =E10-E9 -> 1.53 | H10: =G10/E9 -> 0.02186339 | I10: =MAX(G10,0) -> 1.53 | J10: =MAX(-G10,0) -> 0
A11: 45783 | B11: 71.37 | C11: 71.47 | D11: 70.95 | E11: 71.21 | F11: 41191063 | G11: =E11-E10 -> -0.3 | H11: =G11/E10 -> -0.0041952175 | I11: =MAX(G11,0) -> 0 | J11: =MAX(-G11,0) -> 0.3
A12: 45784 | B12: 69.66 | C12: 69.81 | D12: 69.27 | E12: 69.54 | F12: 29445360 | G12: =E12-E11 -> -1.67 | H12: =G12/E11 -> -0.023451762 | I12: =MAX(G12,0) -> 0 | J12: =MAX(-G12,0) -> 1.67
A13: 45785 | B13: 69.67 | C13: 69.93 | D13: 69.01 | E13: 69.47 | F13: 33059588 | G13: =E13-E12 -> -0.07 | H13: =G13/E12 -> -0.0010066149 | I13: =MAX(G13,0) -> 0 | J13: =MAX(-G13,0) -> 0.07
A14: 45786 | B14: 70.15 | C14: 70.59 | D14: 70.07 | E14: 70.33 | F14: 37687328 | G14: =E14-E13 -> 0.86 | H14: =G14/E13 -> 0.012379444 | I14: =MAX(G14,0) -> 0.86 | J14: =MAX(-G14,0) -> 0 | Q14: =AVERAGE(E3:E14) -> 69.525
A15: 45789 | B15: 70.27 | C15: 70.45 | D15: 70.27 | E15: 70.36 | F15: 21289255 | G15: =E15-E14 -> 0.03 | H15: =G15/E14 -> 0.0004265605 | I15: =MAX(G15,0) -> 0.03 | J15: =MAX(-G15,0) -> 0 | Q15: =Q14+(2/13)*(E15-Q14) -> 69.653462
A16: 45790 | B16: 70.68 | C16: 70.89 | D16: 70.51 | E16: 70.7 | F16: 24363755 | G16: =E16-E15 -> 0.34 | H16: =G16/E15 -> 0.0048322911 | I16: =MAX(G16,0) -> 0.34 | J16: =MAX(-G16,0) -> 0 | Q16: =Q15+(2/13)*(E16-Q15) -> 69.814467
A17: 45791 | B17: 69 | C17: 69 | D17: 68.8 | E17: 68.9 | F17: 32282456 | G17: =E17-E16 -> -1.8 | H17: =G17/E16 -> -0.025459689 | I17: =MAX(G17,0) -> 0 | J17: =MAX(-G17,0) -> 1.8 | K17: =AVERAGE(I4:I17) -> 0.345 | L17: =AVERAGE(J4:J17) -> 0.31642857 | M17: =IF(L17=0,100,100-100/(1+K17/MAX(L17,0.000001))) -> 52.159827 | Q17: =Q16+(2/13)*(E17-Q16) -> 69.67378 | V17: =IF(M17="","",IF(M17<Assumptions!$B$5,"BUY",IF(M17>Assumptions!$B$4,"SELL","HOLD"))) -> HOLD
A18: 45792 | B18: 67.59 | C18: 68.66 | D18: 67.44 | E18: 68.05 | F18: 25972476 | G18: =E18-E17 -> -0.85 | H18: =G18/E17 -> -0.01233672 | I18: =MAX(G18,0) -> 0 | J18: =MAX(-G18,0) -> 0.85 | K18: =(K17*13+I18)/14 -> 0.32035714 | L18: =(L17*13+J18)/14 -> 0.35454082 | M18: =IF(L18=0,100,100-100/(1+K18/MAX(L18,0.000001))) -> 47.467493 | Q18: =Q17+(2/13)*(E18-Q17) -> 69.423968 | V18: =IF(M18="","",IF(M18<Assumptions!$B$5,"BUY",IF(M18>Assumptions!$B$4,"SELL","HOLD"))) -> HOLD
A19: 45793 | B19: 68.81 | C19: 69.09 | D19: 68.13 | E19: 68.61 | F19: 19055706 | G19: =E19-E18 -> 0.56 | H19: =G19/E18 -> 0.0082292432 | I19: =MAX(G19,0) -> 0.56 | J19: =MAX(-G19,0) -> 0 | K19: =(K18*13+I19)/14 -> 0.33747449 | L19: =(L18*13+J19)/14 -> 0.32921647 | M19: =IF(L19=0,100,100-100/(1+K19/MAX(L19,0.000001))) -> 50.619329 | Q19: =Q18+(2/13)*(E19-Q18) -> 69.298742 | V19: =IF(M19="","",IF(M19<Assumptions!$B$5,"BUY",IF(M19>Assumptions!$B$4,"SELL","HOLD"))) -> HOLD
A20: 45796 | B20: 69.69 | C20: 69.73 | D20: 69.11 | E20: 69.42 | F20: 23140500 | G20: =E20-E19 -> 0.81 | H20: =G20/E19 -> 0.011805859 | I20: =MAX(G20,0) -> 0.81 | J20: =MAX(-G20,0) -> 0 | K20: =(K19*13+I20)/14 -> 0.37122631 | L20: =(L19*13+J20)/14 -> 0.30570101 | M20: =IF(L20=0,100,100-100/(1+K20/MAX(L20,0.000001))) -> 54.839907 | Q20: =Q19+(2/13)*(E20-Q19) -> 69.317397 | V20: =IF(M20="","",IF(M20<Assumptions!$B$5,"BUY",IF(M20>Assumptions!$B$4,"SELL","HOLD"))) -> HOLD
